Workbook

Sheet README
B2: Defense Logistics Requisition & Inventory Analytics
B3: End-to-end Excel Data Analyst project — raw data → cleaning → validation → pivot analysis → dashboard
B5: ⚠ IMPORTANT: All data in this workbook is synthetic and fictional, generated for portfolio/demonstration purposes only. It does not represent real Indian Army operations, units, procurement records, or any classified information.
B7: Project Objective
B8: Simulates the requisition (supply-request) workflow across 8 logistics units and 5 regions: units raise requests for stores (rations, spares, medical supplies, communication equipment, etc.), requests get approved/rejected, and approved items get dispatched and delivered. The workbook answers questions a Data Analyst would be asked to answer from a raw export of this kind of system.
B10: Business Questions Answered
B11: • Which units and regions generate the most requisition volume and cost?
B12: • Which item categories account for the largest share of approved spend, and how does spend trend month to month?
B13: • How reliable is delivery performance by region — what's the average delay, and what % of deliveries are on time?
B14: • How much of the raw data is trustworthy, and what specifically is wrong with the rest?
B16: How the Workbook Is Organized
B17: Raw_Data | D17: The messy "as-exported" dataset (300 requisitions) — mixed date formats, currency symbols, typos, inconsistent casing, duplicates, missing values, and logic errors. Left untouched, as a record of the source.
B18: Lookup_Tables | D18: Messy-value → canonical-value maps for Category / Status / Region, used by Cleaned_Data via INDEX/MATCH to fix genuine misspellings (not just casing).
B19: Cleaned_Data | D19: The full cleaning pipeline, entirely formula-driven — every cell recalculates if Raw_Data changes. Adds parsed dates, parsed costs, standardized text, a computed Total_Cost and Delay_Days, and 4 audit flag columns (Is_Duplicate, Missing_Critical_Data, Logic_Error_Flag, Include_In_Analysis) that gate what feeds the analysis downstream.
B20: Data_Cleaning_Log | D20: A plain-English log of every issue type found, the exact technique used to fix it, and a live formula count of affected rows — useful both as documentation and as interview talking points.
B21: New_Entry_Form | D21: A forward-looking data entry template with dropdown lists and range checks (Excel Data Validation) so the same messiness can't enter the system again.
B22: Pivot_Unit_Status | D22: Cross-tab of requisition count and cost by Unit × Status (SUMIFS/COUNTIFS).
B23: Pivot_Category_Month | D23: Cross-tab of total cost by Item Category × Month (SUMIFS).
B24: Pivot_Region_Delay | D24: Delivery performance by region — average delay and % on-time (AVERAGEIFS/COUNTIFS).
B25: Dashboard | D25: KPI summary + 4 charts (cost by category, requisitions by status, monthly cost trend, avg delay by region), all formula-driven from Cleaned_Data.
B27: Techniques Demonstrated
B28: • Data cleaning: TRIM, PROPER, SUBSTITUTE, VALUE, IFERROR, ISNUMBER
B29: • Standardization at scale: INDEX/MATCH lookup tables for typo correction
B30: • Robust date parsing across 3 source formats, including a fixed-width workaround for a real DD/MM/YYYY-vs-locale bug that DATEVALUE alone gets wrong
B31: • Data validation: dropdown lists, whole-number/decimal/date range rules on a live entry form
B32: • Pivot-style analysis: SUMIFS, COUNTIFS, AVERAGEIFS cross-tabs
B33: • KPI dashboard with native Excel charts (bar, pie, line), all formula-linked to source data
B34: • Data quality gating: a single Include_In_Analysis flag keeps bad rows out of every downstream number
B36: How to Use / Extend This Workbook
B37: Everything downstream of Raw_Data is a live formula. To test it: change a value in Raw_Data, open the file in Excel, and press Ctrl+Alt+F9 (full recalculate) — Cleaned_Data, the pivots, the cleaning log counts, and the dashboard will all update. To add real ongoing data, use the New_Entry_Form sheet (dropdowns prevent most of the messiness this project had to clean up).

Sheet Raw_Data
A1: Req_ID | B1: Request_Date | C1: Unit | D1: Region | E1: Item_Category | F1: Item_Name | G1: Quantity_Requested | H1: Quantity_Approved | I1: Unit_Cost_INR | J1: Priority | K1: Status | L1: Requested_By_Role | M1: Approval_Date | N1: Expected_Delivery_Date | O1: Actual_Delivery_Date | P1: Vendor_Supply_Source
A2: REQ-2025-0001 | B2: 25/04/2025 | C2: Unit B - Artillery | D2: southern | E2: communication equipment | F2: Signal Cable (100m) | G2: 307 | I2: 1486.41 | J2: HIGH | K2: PENDING | L2: Quartermaster
A3: REQ-2025-0002 | C3: UNIT B - ARTILLERY | D3: SOUTHERN | E3: FUEL & LUBRICANTS | F3: Kerosene (Drum 200L) | G3: 477 | H3: 452 | I3: ₹27,891 | J3: routine | K3: delivered | L3: Quartermaster | M3: 22/05/2025 | N3: 14/06/2025 | O3: 45823 | P3: SENA SUPPLY CO
A4: REQ-2025-0003 | B4: 46008 | C4: Unit G - Transport Corps | D4: Southern | E4: TENTS & SHELTER | F4: Tarpaulin Sheet | G4: 0 | H4: 331 | I4: 9612.58 | J4: High | K4: approved | L4: Logistics Officer | N4: 23/01/2026 | P4: Om Suppliers
A5: REQ-2025-0004 | B5: 02-Feb-2025 | C5: unit c - engineers | D5: EASTERN | E5: Construciton Material | F5: Barbed Wire Roll | G5: 288 | I5: 32474.37 | J5: Routine | K5: Rejected | L5: Stores Officer | P5: shakti traders
A6: REQ-2025-0005 | C6: Unit C - Engineers | D6: Eastern | E6: TENTS & SHELTER | F6: 10-Man Tent | G6: 480 | H6: 452 | I6: 10,889.44 | J6: high | K6: APPROVED | L6: Quartermaster | M6: 07/11/2025 | N6: 45991 | P6: Sena Supply Co
A7: REQ-2025-0006 | B7: 03-Mar-2025 | C7: Unit F - Ordnance Depot | D7: Nothern | E7: Tents & Shelter | F7: Tent Poles Set | G7: 15 | H7: 11 | I7: 3,334.04 | J7: High | K7: Approved | L7: stores officer | N7: 16/03/2025 | P7: sena supply co
A8: REQ-2025-0007 | C8: Unit A - Infantry | D8: Northern | E8: Vehicle Spares | F8: Truck Tyre 900x20 | G8: 103 | H8: 85 | I8: ₹12,643 | J8: HIGH | K8: delivered | L8: LOGISTICS OFFICER | M8: 45868 | N8: 06-Aug-2025 | O8: 15-Aug-2025 | P8: Sena Supply Co
A9: REQ-2025-0008 | B9: 30-Jan-2025 | C9: UNIT H - AIR DEFENCE | D9: Eastern | E9: Communication Equipment | F9: Signal Cable (100m) | G9: 0 | H9: 33 | I9: 23971.01 | J9: HIGH | K9: Dispatched | L9: stores officer | M9: 45688 | N9: 21/02/2025 | P9: sena supply co
A10: REQ-2025-0009 | B10: 11-Jun-2025 | C10: Unit C - Engineers | D10: EASTERN | E10: Communication Equipment | F10: Antenna Unit | G10: 239 | H10: 174 | I10: 24262.9 | J10: High | L10: Quartermaster | M10: 45828 | N10: 03/07/2025 | O10: 02-Jul-2025 | P10: OM SUPPLIERS
A11: REQ-2025-0010 | B11: 25-May-2025 | C11: UNIT B - ARTILLERY | D11: SOUTHERN | E11: UNIFORMS & CLOTHING | F11: Field Boots (Pair) | G11: 356 | H11: 301 | I11: 40,754.34 | J11: Low | K11: Dispatched | L11: LOGISTICS OFFICER | N11: 45810 | P11: rapid vendors ltd
A12: REQ-2025-0011 | B12: 18-Apr-2025 | C12: UNIT A - INFANTRY | D12: northern | E12: Rations | F12: Rice (50kg bag) | G12: 404 | H12: 400 | I12: 33764.07 | J12: high | K12: delivered | L12: Stores Officer | M12: 45769 | N12: 02-May-2025 | O12: 22/05/2025 | P12: National Defence Stores
A13: REQ-2025-0012 | B13: 45826 | C13: Unit D - Signals | D13: WESTERN | E13: Medical Supplies | F13: Antiseptic Solution (5L) | G13: 184 | H13: 182 | I13: ₹24,199 | J13: High | K13: approved | L13: Stores Officer | N13: 27-Jun-2025 | P13: Shakti Traders
A14: REQ-2025-0013 | B14: 16/11/2025 | C14: unit d - signals | D14: WESTERN | E14: vehicle spares | F14: Engine Oil Filter | G14: 264 | H14: 216 | I14: 13410.14 | J14: HIGH | K14: approved | L14: stores officer | M14: 19/11/2025 | N14: 30/11/2025 | P14: Rapid Vendors Ltd
A15: REQ-2025-0014 | B15: 45997 | C15: Unit C - Engineers | D15: EASTERN | E15: Communication Equipment | F15: Headset Set | G15: 424 | H15: 336 | I15: ₹36,324 | J15: Low | K15: DISPATCHED | L15: Quartermaster | M15: 09-Dec-2025 | P15: BHARAT LOGISTICS PVT LTD
A16: REQ-2025-0015 | B16: 22-Aug-2025 | C16: unit h - air defence | D16: eastern | E16: Medical Supplies | F16: First Aid Kit | G16: 491 | I16: 19,999.42 | J16: Routine | K16: Pending | L16: STORES OFFICER
A17: REQ-2025-0016 | B17: 11/02/2025 | C17: unit d - signals | D17: western | E17: Fuel & Lubricants | F17: Kerosene (Drum 200L) | G17: 360 | I17: 9745.79 | J17: Medium | K17: pending | L17: unit commander | P17: Om Suppliers
A18: REQ-2025-0017 | B18: 23-Apr-2025 | C18: Unit G - Transport Corps | D18: Southern | E18: TENTS & SHELTER | F18: Ground Sheet | G18: -253 | H18: 228 | I18: 18,283.60 | J18: LOW | K18: Dispatched | L18: unit commander | M18: 26-Apr-2025 | N18: 45792 | P18: national defence stores
A19: REQ-2025-0018 | B19: 29/06/2025 | C19: Unit B - Artillery | D19: Southern | E19: TENTS & SHELTER | F19: 10-Man Tent | G19: 0 | H19: 372 | I19: 28016.9 | J19: HIGH | K19: APPROVED | L19: QUARTERMASTER | M19: 45841 | N19: 12/07/2025 | P19: central ordnance suppliers
A20: REQ-2025-0019 | B20: 46014 | C20: unit d - signals | D20: Western | E20: MEDICAL SUPPLIES | F20: First Aid Kit | G20: 182 | H20: 131 | I20: 29,192.31 | J20: High | K20: Delivered | L20: Quartermaster | M20: 24/12/2025 | N20: 46033 | O20: 46043 | P20: sena supply co
A21: REQ-2025-0020 | B21: 09/11/2025 | C21: Unit H - Air Defence | D21: EASTERN | E21: Office & IT Equipment | F21: UPS Backup Unit | G21: 258 | H21: 197 | I21: ₹35,933 | J21: Low | K21: delivered | L21: QUARTERMASTER | M21: 15/11/2025 | N21: 45989 | O21: 12/12/2025 | P21: Shakti Traders
A22: REQ-2025-0021 | B22: 26/12/2025 | C22: unit g - transport corps | D22: Central | E22: Fuel & Lubricants | F22: Engine Grease (5kg) | G22: 123 | H22: 90 | I22: 24183.5 | J22: low | K22: DISPATCHED | L22: STORES OFFICER | N22: 46031 | P22: Vikram Enterprises
A23: REQ-2025-0022 | C23: Unit H - Air Defence | D23: EASTERN | E23: rations | F23: Cooking Oil (15L) | G23: 99 | H23: 94 | I23: 5266.81 | J23: Routine | K23: DISPATCHED | L23: Stores Officer | M23: 28/05/2025 | N23: 45822 | P23: Central Ordnance Suppliers
A24: REQ-2025-0023 | B24: 45708 | C24: UNIT E - MEDICAL CORPS | D24: Central | E24: Rations | F24: Cooking Oil (15L) | G24: 140 | H24: 105 | I24: 3516.66 | J24: Medium | K24: delivered | L24: Logistics Officer | M24: 21/02/2025 | N24: 11-Mar-2025 | O24: 20-Mar-2025 | P24: TBD
A25: REQ-2025-0024 | B25: 05/03/2025 | C25: UNIT E - MEDICAL CORPS | D25: Central | E25: Communication Equipment | F25: Antenna Unit | G25: 487 | H25: 404 | J25: Low | K25: DISPATCHED | L25: Unit Commander | M25: 45728 | N25: 45756 | P25: om suppliers
A26: REQ-2025-0025 | C26: unit h - air defence | D26: Western | E26: Fuel & Lubricants | F26: Hydraulic Fluid (20L) | G26: 173 | H26: 155 | J26: High | K26: Approved | L26: Logistics Officer | M26: 45837 | P26: CENTRAL ORDNANCE SUPPLIERS
A27: REQ-2025-0026 | B27: 15/01/2025 | C27: Unit E - Medical Corps | D27: central | E27: Office & IT Equipment | F27: Desktop Computer | G27: 164 | H27: 119 | I27: ₹44,653 | J27: medium | K27: Delivered | L27: Logistics Officer | M27: 45674 | N27: 05-Feb-2025 | O27: 45691 | P27: National Defence Stores
A28: REQ-2025-0027 | B28: 24/10/2025 | C28: UNIT A - INFANTRY | D28: NORTHERN | E28: Communication Equipment | F28: Headset Set | G28: 233 | H28: 201 | I28: 24522.84 | J28: Routine | K28: Delivered | L28: LOGISTICS OFFICER | M28: 01/11/2025 | N28: 16/11/2025 | O28: 17-Nov-2025 | P28: vikram enterprises
A29: REQ-2025-0028 | B29: 02-Dec-2025 | C29: Unit H - Air Defence | D29: Eastern | E29: Uniforms & Clothing | F29: Rain Poncho | G29: 405 | H29: 367 | I29: ₹29,295 | J29: high | K29: delivered | L29: Unit Commander | M29: 08/12/2025 | O29: 46037 | P29: RAPID VENDORS LTD
A30: REQ-2025-0029 | B30: 11/07/2025 | C30: UNIT F - ORDNANCE DEPOT | D30: NORTHERN | E30: communication equipment | F30: Battery Pack (Radio) | G30: 294 | I30: ₹8,002 | K30: Rejected | L30: UNIT COMMANDER | P30: rapid vendors ltd
A31: REQ-2025-0030 | B31: 45891 | C31: Unit E - Medical Corps | D31: Central | E31: Construciton Material | F31: Sandbag (Pack of 50) | G31: 441 | H31: 384 | I31: 25930.32 | J31: Medium | K31: DELIVERED | L31: UNIT COMMANDER | M31: 45896 | N31: 01-Sep-2025 | O31: 17-Sep-2025 | P31: RAPID VENDORS LTD
A32: REQ-2025-0031 | B32: 18-Jan-2025 | C32: unit b - artillery | D32: Northern | E32: Communication Equipment | F32: Antenna Unit | G32: 470 | H32: 353 | I32: ₹6,077 | J32: Medium | K32: Dispatched | L32: Quartermaster | M32: 27-Jan-2025 | N32: 12-Feb-2025 | P32: shakti traders
A33: REQ-2025-0032 | C33: Unit G - Transport Corps | D33: Southern | E33: TENTS & SHELTER | F33: 10-Man Tent | G33: 426 | I33: 30416.42 | J33: low | K33: rejected | L33: unit commander | P33: CENTRAL ORDNANCE SUPPLIERS
A34: REQ-2025-0033 | B34: 45872 | C34: unit c - engineers | D34: eastern | E34: fuel & lubricants | F34: Kerosene (Drum 200L) | G34: 340 | H34: 279 | I34: 42825.74 | J34: MEDIUM | K34: Dispatched | L34: Unit Commander | N34: 45900 | P34: Om Suppliers
A35: REQ-2025-0034 | B35: 17-Oct-2025 | C35: Unit A - Infantry | D35: NORTHERN | E35: MEDICAL SUPPLIES | F35: Surgical Gloves (Box) | G35: 421 | H35: 313 | I35: 40,538.82 | J35: Medium | L35: logistics officer | N35: 45961 | P35: N/A
A36: REQ-2025-0035 | B36: 31/10/2025 | C36: Unit H - Air Defence | D36: Eastern | E36: Fuel & Lubricants | F36: Kerosene (Drum 200L) | G36: 377 | I36: 39,034.09 | J36: MEDIUM | K36: PENDING | L36: quartermaster
A37: REQ-2025-0036 | B37: 21-Aug-2025 | C37: unit f - ordnance depot | D37: northern | E37: tents & shelter | F37: Camouflage Net | G37: 411 | H37: 367 | I37: ₹34,638 | J37: Routine | K37: DISPATCHED | L37: QUARTERMASTER | M37: 45894 | N37: 12/09/2025 | P37: CENTRAL ORDNANCE SUPPLIERS
A38: REQ-2025-0037 | C38: Unit A - Infantry | D38: Northern | E38: tents & shelter | F38: Ground Sheet | G38: 452 | H38: 434 | I38: 32489.57 | J38: routine | K38: Delivered | L38: Stores Officer | M38: 23/06/2025 | N38: 17/07/2025 | O38: 21/07/2025 | P38: Om Suppliers
A39: REQ-2025-0038 | C39: Unit E - Medical Corps | D39: Central | E39: communication equipment | F39: Battery Pack (Radio) | G39: 294 | I39: ₹33,382 | J39: Medium | K39: Rejected | L39: LOGISTICS OFFICER
A40: REQ-2025-0039 | B40: 45797 | C40: Unit G - Transport Corps | D40: southren | E40: Office & IT Equipment | F40: Filing Cabinet | G40: 225 | H40: 197 | I40: 23782.99 | J40: HIGH | K40: APPROVED | L40: Stores Officer | M40: 45802 | N40: 31/05/2025 | P40: vikram enterprises
...

Sheet Lookup_Tables
A1: Standardization Lookup Tables
A2: Used by Cleaned_Data (INDEX/MATCH) to correct typos and inconsistent spelling found in Raw_Data. MATCH() is case-insensitive and cells are wrapped in TRIM(), so spacing/case issues never need a row here — only genuine misspellings do.
A4: Item_Category Map | D4: Status Map | G4: Region Map
A5: Messy_Value | B5: Canonical_Value | D5: Messy_Value | E5: Canonical_Value | G5: Messy_Value | H5: Canonical_Value
A6: Rations | B6: Rations | D6: Pending | E6: Pending | G6: Northern | H6: Northern
A7: Vehicle Spares | B7: Vehicle Spares | D7: Approved | E7: Approved | G7: Southern | H7: Southern
A8: Uniforms & Clothing | B8: Uniforms & Clothing | D8: Rejected | E8: Rejected | G8: Eastern | H8: Eastern
A9: Medical Supplies | B9: Medical Supplies | D9: Dispatched | E9: Dispatched | G9: Western | H9: Western
A10: Communication Equipment | B10: Communication Equipment | D10: Delivered | E10: Delivered | G10: Central | H10: Central
A11: Fuel & Lubricants | B11: Fuel & Lubricants | D11: Pendng | E11: Pending | G11: Nothern | H11: Northern
A12: Construction Material | B12: Construction Material | D12: Approvd | E12: Approved | G12: southren | H12: Southern
A13: Office & IT Equipment | B13: Office & IT Equipment | D13: Dispached | E13: Dispatched
A14: Tents & Shelter | B14: Tents & Shelter
A15: Raitons | B15: Rations
A16: Medcial Supplies | B16: Medical Supplies
A17: Comunication Equipment | B17: Communication Equipment
A18: Construciton Material | B18: Construction Material

Sheet Cleaned_Data
A1: Req_ID | B1: Request_Date | C1: Unit | D1: Region | E1: Item_Category | F1: Item_Name | G1: Quantity_Requested | H1: Quantity_Approved | I1: Unit_Cost_INR | J1: Priority | K1: Status | L1: Requested_By_Role | M1: Approval_Date | N1: Expected_Delivery_Date | O1: Actual_Delivery_Date | P1: Vendor | Q1: Total_Cost_INR | R1: Delay_Days | S1: Is_Duplicate | T1: Missing_Critical_Data | U1: Logic_Error_Flag | V1: Include_In_Analysis | W1: Request_Month
A2: =TRIM(Raw_Data!A2) -> REQ-2025-0001 | B2: =IF(Raw_Data!B2="","",IF(ISNUMBER(Raw_Data!B2),Raw_Data!B2,IF(ISNUMBER(SEARCH("/",Raw_Data!B2)),IFERROR(DATE(VALUE(RIGHT(Raw_Data!B2,4)),VALUE(MID(Raw_Data!B2,4,2)),VALUE(LEFT(Raw_Data!B2,2))),"Invalid Date"),IFERROR(DATEVALUE(Raw_Data!B2),"Invalid Date")))) -> 45772 | C2: =IF(TRIM(Raw_Data!C2)="","",PROPER(TRIM(Raw_Data!C2))) -> Unit B - Artillery | D2: =IF(TRIM(Raw_Data!D2)="","Not Specified",IFERROR(INDEX(Lookup_Tables!$H$6:$H$12,MATCH(TRIM(Raw_Data!D2),Lookup_Tables!$G$6:$G$12,0)),"Unknown - Review")) -> Southern | E2: =IF(TRIM(Raw_Data!E2)="","Not Specified",IFERROR(INDEX(Lookup_Tables!$B$6:$B$18,MATCH(TRIM(Raw_Data!E2),Lookup_Tables!$A$6:$A$18,0)),"Unknown - Review")) -> Communication Equipment | F2: =IF(TRIM(Raw_Data!F2)="","",TRIM(Raw_Data!F2)) -> Signal Cable (100m) | G2: =IF(Raw_Data!G2="","",IF(VALUE(Raw_Data!G2)<=0,"Invalid",VALUE(Raw_Data!G2))) -> 307 | H2: =IF(Raw_Data!H2="","",IF(VALUE(Raw_Data!H2)<=0,"Invalid",VALUE(Raw_Data!H2))) | I2: =IFERROR(VALUE(SUBSTITUTE(SUBSTITUTE(Raw_Data!I2,"₹",""),",","")),"") -> 1486.41 | J2: =IF(TRIM(Raw_Data!J2)="","Not Specified",PROPER(TRIM(Raw_Data!J2))) -> High | K2: =IF(TRIM(Raw_Data!K2)="","Not Specified",IFERROR(INDEX(Lookup_Tables!$E$6:$E$13,MATCH(TRIM(Raw_Data!K2),Lookup_Tables!$D$6:$D$13,0)),"Unknown - Review")) -> Pending | L2: =IF(TRIM(Raw_Data!L2)="","",PROPER(TRIM(Raw_Data!L2))) -> Quartermaster | M2: =IF(Raw_Data!M2="","",IF(ISNUMBER(Raw_Data!M2),Raw_Data!M2,IF(ISNUMBER(SEARCH("/",Raw_Data!M2)),IFERROR(DATE(VALUE(RIGHT(Raw_Data!M2,4)),VALUE(MID(Raw_Data!M2,4,2)),VALUE(LEFT(Raw_Data!M2,2))),"Invalid Date"),IFERROR(DATEVALUE(Raw_Data!M2),"Invalid Date")))) | N2: =IF(Raw_Data!N2="","",IF(ISNUMBER(Raw_Data!N2),Raw_Data!N2,IF(ISNUMBER(SEARCH("/",Raw_Data!N2)),IFERROR(DATE(VALUE(RIGHT(Raw_Data!N2,4)),VALUE(MID(Raw_Data!N2,4,2)),VALUE(LEFT(Raw_Data!N2,2))),"Invalid Date"),IFERROR(DATEVALUE(Raw_Data!N2),"Invalid Date")))) | O2: =IF(Raw_Data!O2="","",IF(ISNUMBER(Raw_Data!O2),Raw_Data!O2,IF(ISNUMBER(SEARCH("/",Raw_Data!O2)),IFERROR(DATE(VALUE(RIGHT(Raw_Data!O2,4)),VALUE(MID(Raw_Data!O2,4,2)),VALUE(LEFT(Raw_Data!O2,2))),"Invalid Date"),IFERROR(DATEVALUE(Raw_Data!O2),"Invalid Date")))) | P2: =IF(OR(TRIM(Raw_Data!P2)="",TRIM(Raw_Data!P2)="N/A",TRIM(Raw_Data!P2)="TBD",TRIM(Raw_Data!P2)="-"),"Not Assigned",PROPER(TRIM(Raw_Data!P2))) -> Not Assigned | Q2: =IF(OR(H2="",I2="",NOT(ISNUMBER(H2)),NOT(ISNUMBER(I2))),"",H2*I2) | R2: =IF(AND(ISNUMBER(O2),ISNUMBER(N2)),O2-N2,"") | S2: =IF(COUNTIF($A$2:A2,A2)>1,"Duplicate","Unique") -> Unique | T2: =IF(OR(G2="",K2="Not Specified",C2=""),"Yes","No") -> No | U2: =IF(OR(AND(ISNUMBER(H2),ISNUMBER(G2),H2>G2),AND(K2="Rejected",ISNUMBER(H2),H2>0)),"Yes","No") -> No | V2: =IF(AND(S2="Unique",T2="No",U2="No",G2<>"Invalid",H2<>"Invalid"),"Yes","No") -> Yes | W2: =IF(ISNUMBER(B2),TEXT(B2,"MMM-YYYY"),"") -> Apr-2025
A3: =TRIM(Raw_Data!A3) -> REQ-2025-0002 | B3: =IF(Raw_Data!B3="","",IF(ISNUMBER(Raw_Data!B3),Raw_Data!B3,IF(ISNUMBER(SEARCH("/",Raw_Data!B3)),IFERROR(DATE(VALUE(RIGHT(Raw_Data!B3,4)),VALUE(MID(Raw_Data!B3,4,2)),VALUE(LEFT(Raw_Data!B3,2))),"Invalid Date"),IFERROR(DATEVALUE(Raw_Data!B3),"Invalid Date")))) | C3: =IF(TRIM(Raw_Data!C3)="","",PROPER(TRIM(Raw_Data!C3))) -> Unit B - Artillery | D3: =IF(TRIM(Raw_Data!D3)="","Not Specified",IFERROR(INDEX(Lookup_Tables!$H$6:$H$12,MATCH(TRIM(Raw_Data!D3),Lookup_Tables!$G$6:$G$12,0)),"Unknown - Review")) -> Southern | E3: =IF(TRIM(Raw_Data!E3)="","Not Specified",IFERROR(INDEX(Lookup_Tables!$B$6:$B$18,MATCH(TRIM(Raw_Data!E3),Lookup_Tables!$A$6:$A$18,0)),"Unknown - Review")) -> Fuel & Lubricants | F3: =IF(TRIM(Raw_Data!F3)="","",TRIM(Raw_Data!F3)) -> Kerosene (Drum 200L) | G3: =IF(Raw_Data!G3="","",IF(VALUE(Raw_Data!G3)<=0,"Invalid",VALUE(Raw_Data!G3))) -> 477 | H3: =IF(Raw_Data!H3="","",IF(VALUE(Raw_Data!H3)<=0,"Invalid",VALUE(Raw_Data!H3))) -> 452 | I3: =IFERROR(VALUE(SUBSTITUTE(SUBSTITUTE(Raw_Data!I3,"₹",""),",","")),"") -> 27891 | J3: =IF(TRIM(Raw_Data!J3)="","Not Specified",PROPER(TRIM(Raw_Data!J3))) -> Routine | K3: =IF(TRIM(Raw_Data!K3)="","Not Specified",IFERROR(INDEX(Lookup_Tables!$E$6:$E$13,MATCH(TRIM(Raw_Data!K3),Lookup_Tables!$D$6:$D$13,0)),"Unknown - Review")) -> Delivered | L3: =IF(TRIM(Raw_Data!L3)="","",PROPER(TRIM(Raw_Data!L3))) -> Quartermaster | M3: =IF(Raw_Data!M3="","",IF(ISNUMBER(Raw_Data!M3),Raw_Data!M3,IF(ISNUMBER(SEARCH("/",Raw_Data!M3)),IFERROR(DATE(VALUE(RIGHT(Raw_Data!M3,4)),VALUE(MID(Raw_Data!M3,4,2)),VALUE(LEFT(Raw_Data!M3,2))),"Invalid Date"),IFERROR(DATEVALUE(Raw_Data!M3),"Invalid Date")))) -> 45799 | N3: =IF(Raw_Data!N3="","",IF(ISNUMBER(Raw_Data!N3),Raw_Data!N3,IF(ISNUMBER(SEARCH("/",Raw_Data!N3)),IFERROR(DATE(VALUE(RIGHT(Raw_Data!N3,4)),VALUE(MID(Raw_Data!N3,4,2)),VALUE(LEFT(Raw_Data!N3,2))),"Invalid Date"),IFERROR(DATEVALUE(Raw_Data!N3),"Invalid Date")))) -> 45822 | O3: =IF(Raw_Data!O3="","",IF(ISNUMBER(Raw_Data!O3),Raw_Data!O3,IF(ISNUMBER(SEARCH("/",Raw_Data!O3)),IFERROR(DATE(VALUE(RIGHT(Raw_Data!O3,4)),VALUE(MID(Raw_Data!O3,4,2)),VALUE(LEFT(Raw_Data!O3,2))),"Invalid Date"),IFERROR(DATEVALUE(Raw_Data!O3),"Invalid Date")))) -> 45823 | P3: =IF(OR(TRIM(Raw_Data!P3)="",TRIM(Raw_Data!P3)="N/A",TRIM(Raw_Data!P3)="TBD",TRIM(Raw_Data!P3)="-"),"Not Assigned",PROPER(TRIM(Raw_Data!P3))) -> Sena Supply Co | Q3: =IF(OR(H3="",I3="",NOT(ISNUMBER(H3)),NOT(ISNUMBER(I3))),"",H3*I3) -> 12606732 | R3: =IF(AND(ISNUMBER(O3),ISNUMBER(N3)),O3-N3,"") -> 1 | S3: =IF(COUNTIF($A$2:A3,A3)>1,"Duplicate","Unique") -> Unique | T3: =IF(OR(G3="",K3="Not Specified",C3=""),"Yes","No") -> No | U3: =IF(OR(AND(ISNUMBER(H3),ISNUMBER(G3),H3>G3),AND(K3="Rejected",ISNUMBER(H3),H3>0)),"Yes","No") -> No | V3: =IF(AND(S3="Unique",T3="No",U3="No",G3<>"Invalid",H3<>"Invalid"),"Yes","No") -> Yes | W3: =IF(ISNUMBER(B3),TEXT(B3,"MMM-YYYY"),"")
A4: =TRIM(Raw_Data!A4) -> REQ-2025-0003 | B4: =IF(Raw_Data!B4="","",IF(ISNUMBER(Raw_Data!B4),Raw_Data!B4,IF(ISNUMBER(SEARCH("/",Raw_Data!B4)),IFERROR(DATE(VALUE(RIGHT(Raw_Data!B4,4)),VALUE(MID(Raw_Data!B4,4,2)),VALUE(LEFT(Raw_Data!B4,2))),"Invalid Date"),IFERROR(DATEVALUE(Raw_Data!B4),"Invalid Date")))) -> 46008 | C4: =IF(TRIM(Raw_Data!C4)="","",PROPER(TRIM(Raw_Data!C4))) -> Unit G - Transport Corps | D4: =IF(TRIM(Raw_Data!D4)="","Not Specified",IFERROR(INDEX(Lookup_Tables!$H$6:$H$12,MATCH(TRIM(Raw_Data!D4),Lookup_Tables!$G$6:$G$12,0)),"Unknown - Review")) -> Southern | E4: =IF(TRIM(Raw_Data!E4)="","Not Specified",IFERROR(INDEX(Lookup_Tables!$B$6:$B$18,MATCH(TRIM(Raw_Data!E4),Lookup_Tables!$A$6:$A$18,0)),"Unknown - Review")) -> Tents & Shelter | F4: =IF(TRIM(Raw_Data!F4)="","",TRIM(Raw_Data!F4)) -> Tarpaulin Sheet | G4: =IF(Raw_Data!G4="","",IF(VALUE(Raw_Data!G4)<=0,"Invalid",VALUE(Raw_Data!G4))) -> Invalid | H4: =IF(Raw_Data!H4="","",IF(VALUE(Raw_Data!H4)<=0,"Invalid",VALUE(Raw_Data!H4))) -> 331 | I4: =IFERROR(VALUE(SUBSTITUTE(SUBSTITUTE(Raw_Data!I4,"₹",""),",","")),"") -> 9612.58 | J4: =IF(TRIM(Raw_Data!J4)="","Not Specified",PROPER(TRIM(Raw_Data!J4))) -> High | K4: =IF(TRIM(Raw_Data!K4)="","Not Specified",IFERROR(INDEX(Lookup_Tables!$E$6:$E$13,MATCH(TRIM(Raw_Data!K4),Lookup_Tables!$D$6:$D$13,0)),"Unknown - Review")) -> Approved | L4: =IF(TRIM(Raw_Data!L4)="","",PROPER(TRIM(Raw_Data!L4))) -> Logistics Officer | M4: =IF(Raw_Data!M4="","",IF(ISNUMBER(Raw_Data!M4),Raw_Data!M4,IF(ISNUMBER(SEARCH("/",Raw_Data!M4)),IFERROR(DATE(VALUE(RIGHT(Raw_Data!M4,4)),VALUE(MID(Raw_Data!M4,4,2)),VALUE(LEFT(Raw_Data!M4,2))),"Invalid Date"),IFERROR(DATEVALUE(Raw_Data!M4),"Invalid Date")))) | N4: =IF(Raw_Data!N4="","",IF(ISNUMBER(Raw_Data!N4),Raw_Data!N4,IF(ISNUMBER(SEARCH("/",Raw_Data!N4)),IFERROR(DATE(VALUE(RIGHT(Raw_Data!N4,4)),VALUE(MID(Raw_Data!N4,4,2)),VALUE(LEFT(Raw_Data!N4,2))),"Invalid Date"),IFERROR(DATEVALUE(Raw_Data!N4),"Invalid Date")))) -> 46045 | O4: =IF(Raw_Data!O4="","",IF(ISNUMBER(Raw_Data!O4),Raw_Data!O4,IF(ISNUMBER(SEARCH("/",Raw_Data!O4)),IFERROR(DATE(VALUE(RIGHT(Raw_Data!O4,4)),VALUE(MID(Raw_Data!O4,4,2)),VALUE(LEFT(Raw_Data!O4,2))),"Invalid Date"),IFERROR(DATEVALUE(Raw_Data!O4),"Invalid Date")))) | P4: =IF(OR(TRIM(Raw_Data!P4)="",TRIM(Raw_Data!P4)="N/A",TRIM(Raw_Data!P4)="TBD",TRIM(Raw_Data!P4)="-"),"Not Assigned",PROPER(TRIM(Raw_Data!P4))) -> Om Suppliers | Q4: =IF(OR(H4="",I4="",NOT(ISNUMBER(H4)),NOT(ISNUMBER(I4))),"",H4*I4) -> 3181764 | R4: =IF(AND(ISNUMBER(O4),ISNUMBER(N4)),O4-N4,"") | S4: =IF(COUNTIF($A$2:A4,A4)>1,"Duplicate","Unique") -> Unique | T4: =IF(OR(G4="",K4="Not Specified",C4=""),"Yes","No") -> No | U4: =IF(OR(AND(ISNUMBER(H4),ISNUMBER(G4),H4>G4),AND(K4="Rejected",ISNUMBER(H4),H4>0)),"Yes","No") -> No | V4: =IF(AND(S4="Unique",T4="No",U4="No",G4<>"Invalid",H4<>"Invalid"),"Yes","No") -> No | W4: =IF(ISNUMBER(B4),TEXT(B4,"MMM-YYYY"),"") -> Dec-2025
A5: =TRIM(Raw_Data!A5) -> REQ-2025-0004 | B5: =IF(Raw_Data!B5="","",IF(ISNUMBER(Raw_Data!B5),Raw_Data!B5,IF(ISNUMBER(SEARCH("/",Raw_Data!B5)),IFERROR(DATE(VALUE(RIGHT(Raw_Data!B5,4)),VALUE(MID(Raw_Data!B5,4,2)),VALUE(LEFT(Raw_Data!B5,2))),"Invalid Date"),IFERROR(DATEVALUE(Raw_Data!B5),"Invalid Date")))) -> 45690 | C5: =IF(TRIM(Raw_Data!C5)="","",PROPER(TRIM(Raw_Data!C5))) -> Unit C - Engineers | D5: =IF(TRIM(Raw_Data!D5)="","Not Specified",IFERROR(INDEX(Lookup_Tables!$H$6:$H$12,MATCH(TRIM(Raw_Data!D5),Lookup_Tables!$G$6:$G$12,0)),"Unknown - Review")) -> Eastern | E5: =IF(TRIM(Raw_Data!E5)="","Not Specified",IFERROR(INDEX(Lookup_Tables!$B$6:$B$18,MATCH(TRIM(Raw_Data!E5),Lookup_Tables!$A$6:$A$18,0)),"Unknown - Review")) -> Construction Material | F5: =IF(TRIM(Raw_Data!F5)="","",TRIM(Raw_Data!F5)) -> Barbed Wire Roll | G5: =IF(Raw_Data!G5="","",IF(VALUE(Raw_Data!G5)<=0,"Invalid",VALUE(Raw_Data!G5))) -> 288 | H5: =IF(Raw_Data!H5="","",IF(VALUE(Raw_Data!H5)<=0,"Invalid",VALUE(Raw_Data!H5))) | I5: =IFERROR(VALUE(SUBSTITUTE(SUBSTITUTE(Raw_Data!I5,"₹",""),",","")),"") -> 32474.37 | J5: =IF(TRIM(Raw_Data!J5)="","Not Specified",PROPER(TRIM(Raw_Data!J5))) -> Routine | K5: =IF(TRIM(Raw_Data!K5)="","Not Specified",IFERROR(INDEX(Lookup_Tables!$E$6:$E$13,MATCH(TRIM(Raw_Data!K5),Lookup_Tables!$D$6:$D$13,0)),"Unknown - Review")) -> Rejected | L5: =IF(TRIM(Raw_Data!L5)="","",PROPER(TRIM(Raw_Data!L5))) -> Stores Officer | M5: =IF(Raw_Data!M5="","",IF(ISNUMBER(Raw_Data!M5),Raw_Data!M5,IF(ISNUMBER(SEARCH("/",Raw_Data!M5)),IFERROR(DATE(VALUE(RIGHT(Raw_Data!M5,4)),VALUE(MID(Raw_Data!M5,4,2)),VALUE(LEFT(Raw_Data!M5,2))),"Invalid Date"),IFERROR(DATEVALUE(Raw_Data!M5),"Invalid Date")))) | N5: =IF(Raw_Data!N5="","",IF(ISNUMBER(Raw_Data!N5),Raw_Data!N5,IF(ISNUMBER(SEARCH("/",Raw_Data!N5)),IFERROR(DATE(VALUE(RIGHT(Raw_Data!N5,4)),VALUE(MID(Raw_Data!N5,4,2)),VALUE(LEFT(Raw_Data!N5,2))),"Invalid Date"),IFERROR(DATEVALUE(Raw_Data!N5),"Invalid Date")))) | O5: =IF(Raw_Data!O5="","",IF(ISNUMBER(Raw_Data!O5),Raw_Data!O5,IF(ISNUMBER(SEARCH("/",Raw_Data!O5)),IFERROR(DATE(VALUE(RIGHT(Raw_Data!O5,4)),VALUE(MID(Raw_Data!O5,4,2)),VALUE(LEFT(Raw_Data!O5,2))),"Invalid Date"),IFERROR(DATEVALUE(Raw_Data!O5),"Invalid Date")))) | P5: =IF(OR(TRIM(Raw_Data!P5)="",TRIM(Raw_Data!P5)="N/A",TRIM(Raw_Data!P5)="TBD",TRIM(Raw_Data!P5)="-"),"Not Assigned",PROPER(TRIM(Raw_Data!P5))) -> Shakti Traders | Q5: =IF(OR(H5="",I5="",NOT(ISNUMBER(H5)),NOT(ISNUMBER(I5))),"",H5*I5) | R5: =IF(AND(ISNUMBER(O5),ISNUMBER(N5)),O5-N5,"") | S5: =IF(COUNTIF($A$2:A5,A5)>1,"Duplicate","Unique") -> Unique | T5: =IF(OR(G5="",K5="Not Specified",C5=""),"Yes","No") -> No | U5: =IF(OR(AND(ISNUMBER(H5),ISNUMBER(G5),H5>G5),AND(K5="Rejected",ISNUMBER(H5),H5>0)),"Yes","No") -> No | V5: =IF(AND(S5="Unique",T5="No",U5="No",G5<>"Invalid",H5<>"Invalid"),"Yes","No") -> Yes | W5: =IF(ISNUMBER(B5),TEXT(B5,"MMM-YYYY"),"") -> Feb-2025
A6: =TRIM(Raw_Data!A6) -> REQ-2025-0005 | B6: =IF(Raw_Data!B6="","",IF(ISNUMBER(Raw_Data!B6),Raw_Data!B6,IF(ISNUMBER(SEARCH("/",Raw_Data!B6)),IFERROR(DATE(VALUE(RIGHT(Raw_Data!B6,4)),VALUE(MID(Raw_Data!B6,4,2)),VALUE(LEFT(Raw_Data!B6,2))),"Invalid Date"),IFERROR(DATEVALUE(Raw_Data!B6),"Invalid Date")))) | C6: =IF(TRIM(Raw_Data!C6)="","",PROPER(TRIM(Raw_Data!C6))) -> Unit C - Engineers | D6: =IF(TRIM(Raw_Data!D6)="","Not Specified",IFERROR(INDEX(Lookup_Tables!$H$6:$H$12,MATCH(TRIM(Raw_Data!D6),Lookup_Tables!$G$6:$G$12,0)),"Unknown - Review")) -> Eastern | E6: =IF(TRIM(Raw_Data!E6)="","Not Specified",IFERROR(INDEX(Lookup_Tables!$B$6:$B$18,MATCH(TRIM(Raw_Data!E6),Lookup_Tables!$A$6:$A$18,0)),"Unknown - Review")) -> Tents & Shelter | F6: =IF(TRIM(Raw_Data!F6)="","",TRIM(Raw_Data!F6)) -> 10-Man Tent | G6: =IF(Raw_Data!G6="","",IF(VALUE(Raw_Data!G6)<=0,"Invalid",VALUE(Raw_Data!G6))) -> 480 | H6: =IF(Raw_Data!H6="","",IF(VALUE(Raw_Data!H6)<=0,"Invalid",VALUE(Raw_Data!H6))) -> 452 | I6: =IFERROR(VALUE(SUBSTITUTE(SUBSTITUTE(Raw_Data!I6,"₹",""),",","")),"") -> 10889.44 | J6: =IF(TRIM(Raw_Data!J6)="","Not Specified",PROPER(TRIM(Raw_Data!J6))) -> High | K6: =IF(TRIM(Raw_Data!K6)="","Not Specified",IFERROR(INDEX(Lookup_Tables!$E$6:$E$13,MATCH(TRIM(Raw_Data!K6),Lookup_Tables!$D$6:$D$13,0)),"Unknown - Review")) -> Approved | L6: =IF(TRIM(Raw_Data!L6)="","",PROPER(TRIM(Raw_Data!L6))) -> Quartermaster | M6: =IF(Raw_Data!M6="","",IF(ISNUMBER(Raw_Data!M6),Raw_Data!M6,IF(ISNUMBER(SEARCH("/",Raw_Data!M6)),IFERROR(DATE(VALUE(RIGHT(Raw_Data!M6,4)),VALUE(MID(Raw_Data!M6,4,2)),VALUE(LEFT(Raw_Data!M6,2))),"Invalid Date"),IFERROR(DATEVALUE(Raw_Data!M6),"Invalid Date")))) -> 45968 | N6: =IF(Raw_Data!N6="","",IF(ISNUMBER(Raw_Data!N6),Raw_Data!N6,IF(ISNUMBER(SEARCH("/",Raw_Data!N6)),IFERROR(DATE(VALUE(RIGHT(Raw_Data!N6,4)),VALUE(MID(Raw_Data!N6,4,2)),VALUE(LEFT(Raw_Data!N6,2))),"Invalid Date"),IFERROR(DATEVALUE(Raw_Data!N6),"Invalid Date")))) -> 45991 | O6: =IF(Raw_Data!O6="","",IF(ISNUMBER(Raw_Data!O6),Raw_Data!O6,IF(ISNUMBER(SEARCH("/",Raw_Data!O6)),IFERROR(DATE(VALUE(RIGHT(Raw_Data!O6,4)),VALUE(MID(Raw_Data!O6,4,2)),VALUE(LEFT(Raw_Data!O6,2))),"Invalid Date"),IFERROR(DATEVALUE(Raw_Data!O6),"Invalid Date")))) | P6: =IF(OR(TRIM(Raw_Data!P6)="",TRIM(Raw_Data!P6)="N/A",TRIM(Raw_Data!P6)="TBD",TRIM(Raw_Data!P6)="-"),"Not Assigned",PROPER(TRIM(Raw_Data!P6))) -> Sena Supply Co | Q6: =IF(OR(H6="",I6="",NOT(ISNUMBER(H6)),NOT(ISNUMBER(I6))),"",H6*I6) -> 4922026.9 | R6: =IF(AND(ISNUMBER(O6),ISNUMBER(N6)),O6-N6,"") | S6: =IF(COUNTIF($A$2:A6,A6)>1,"Duplicate","Unique") -> Unique | T6: =IF(OR(G6="",K6="Not Specified",C6=""),"Yes","No") -> No | U6: =IF(OR(AND(ISNUMBER(H6),ISNUMBER(G6),H6>G6),AND(K6="Rejected",ISNUMBER(H6),H6>0)),"Yes","No") -> No | V6: =IF(AND(S6="Unique",T6="No",U6="No",G6<>"Invalid",H6<>"Invalid"),"Yes","No") -> Yes | W6: =IF(ISNUMBER(B6),TEXT(B6,"MMM-YYYY"),"")
A7: =TRIM(Raw_Data!A7) -> REQ-2025-0006 | B7: =IF(Raw_Data!B7="","",IF(ISNUMBER(Raw_Data!B7),Raw_Data!B7,IF(ISNUMBER(SEARCH("/",Raw_Data!B7)),IFERROR(DATE(VALUE(RIGHT(Raw_Data!B7,4)),VALUE(MID(Raw_Data!B7,4,2)),VALUE(LEFT(Raw_Data!B7,2))),"Invalid Date"),IFERROR(DATEVALUE(Raw_Data!B7),"Invalid Date")))) -> 45719 | C7: =IF(TRIM(Raw_Data!C7)="","",PROPER(TRIM(Raw_Data!C7))) -> Unit F - Ordnance Depot | D7: =IF(TRIM(Raw_Data!D7)="","Not Specified",IFERROR(INDEX(Lookup_Tables!$H$6:$H$12,MATCH(TRIM(Raw_Data!D7),Lookup_Tables!$G$6:$G$12,0)),"Unknown - Review")) -> Northern | E7: =IF(TRIM(Raw_Data!E7)="","Not Specified",IFERROR(INDEX(Lookup_Tables!$B$6:$B$18,MATCH(TRIM(Raw_Data!E7),Lookup_Tables!$A$6:$A$18,0)),"Unknown - Review")) -> Tents & Shelter | F7: =IF(TRIM(Raw_Data!F7)="","",TRIM(Raw_Data!F7)) -> Tent Poles Set | G7: =IF(Raw_Data!G7="","",IF(VALUE(Raw_Data!G7)<=0,"Invalid",VALUE(Raw_Data!G7))) -> 15 | H7: =IF(Raw_Data!H7="","",IF(VALUE(Raw_Data!H7)<=0,"Invalid",VALUE(Raw_Data!H7))) -> 11 | I7: =IFERROR(VALUE(SUBSTITUTE(SUBSTITUTE(Raw_Data!I7,"₹",""),",","")),"") -> 3334.04 | J7: =IF(TRIM(Raw_Data!J7)="","Not Specified",PROPER(TRIM(Raw_Data!J7))) -> High | K7: =IF(TRIM(Raw_Data!K7)="","Not Specified",IFERROR(INDEX(Lookup_Tables!$E$6:$E$13,MATCH(TRIM(Raw_Data!K7),Lookup_Tables!$D$6:$D$13,0)),"Unknown - Review")) -> Approved | L7: =IF(TRIM(Raw_Data!L7)="","",PROPER(TRIM(Raw_Data!L7))) -> Stores Officer | M7: =IF(Raw_Data!M7="","",IF(ISNUMBER(Raw_Data!M7),Raw_Data!M7,IF(ISNUMBER(SEARCH("/",Raw_Data!M7)),IFERROR(DATE(VALUE(RIGHT(Raw_Data!M7,4)),VALUE(MID(Raw_Data!M7,4,2)),VALUE(LEFT(Raw_Data!M7,2))),"Invalid Date"),IFERROR(DATEVALUE(Raw_Data!M7),"Invalid Date")))) | N7: =IF(Raw_Data!N7="","",IF(ISNUMBER(Raw_Data!N7),Raw_Data!N7,IF(ISNUMBER(SEARCH("/",Raw_Data!N7)),IFERROR(DATE(VALUE(RIGHT(Raw_Data!N7,4)),VALUE(MID(Raw_Data!N7,4,2)),VALUE(LEFT(Raw_Data!N7,2))),"Invalid Date"),IFERROR(DATEVALUE(Raw_Data!N7),"Invalid Date")))) -> 45732 | O7: =IF(Raw_Data!O7="","",IF(ISNUMBER(Raw_Data!O7),Raw_Data!O7,IF(ISNUMBER(SEARCH("/",Raw_Data!O7)),IFERROR(DATE(VALUE(RIGHT(Raw_Data!O7,4)),VALUE(MID(Raw_Data!O7,4,2)),VALUE(LEFT(Raw_Data!O7,2))),"Invalid Date"),IFERROR(DATEVALUE(Raw_Data!O7),"Invalid Date")))) | P7: =IF(OR(TRIM(Raw_Data!P7)="",TRIM(Raw_Data!P7)="N/A",TRIM(Raw_Data!P7)="TBD",TRIM(Raw_Data!P7)="-"),"Not Assigned",PROPER(TRIM(Raw_Data!P7))) -> Sena Supply Co | Q7: =IF(OR(H7="",I7="",NOT(ISNUMBER(H7)),NOT(ISNUMBER(I7))),"",H7*I7) -> 36674.44 | R7: =IF(AND(ISNUMBER(O7),ISNUMBER(N7)),O7-N7,"") | S7: =IF(COUNTIF($A$2:A7,A7)>1,"Duplicate","Unique") -> Unique | T7: =IF(OR(G7="",K7="Not Specified",C7=""),"Yes","No") -> No | U7: =IF(OR(AND(ISNUMBER(H7),ISNUMBER(G7),H7>G7),AND(K7="Rejected",ISNUMBER(H7),H7>0)),"Yes","No") -> No | V7: =IF(AND(S7="Unique",T7="No",U7="No",G7<>"Invalid",H7<>"Invalid"),"Yes","No") -> Yes | W7: =IF(ISNUMBER(B7),TEXT(B7,"MMM-YYYY"),"") -> Mar-2025
A8: =TRIM(Raw_Data!A8) -> REQ-2025-0007 | B8: =IF(Raw_Data!B8="","",IF(ISNUMBER(Raw_Data!B8),Raw_Data!B8,IF(ISNUMBER(SEARCH("/",Raw_Data!B8)),IFERROR(DATE(VALUE(RIGHT(Raw_Data!B8,4)),VALUE(MID(Raw_Data!B8,4,2)),VALUE(LEFT(Raw_Data!B8,2))),"Invalid Date"),IFERROR(DATEVALUE(Raw_Data!B8),"Invalid Date")))) | C8: =IF(TRIM(Raw_Data!C8)="","",PROPER(TRIM(Raw_Data!C8))) -> Unit A - Infantry | D8: =IF(TRIM(Raw_Data!D8)="","Not Specified",IFERROR(INDEX(Lookup_Tables!$H$6:$H$12,MATCH(TRIM(Raw_Data!D8),Lookup_Tables!$G$6:$G$12,0)),"Unknown - Review")) -> Northern | E8: =IF(TRIM(Raw_Data!E8)="","Not Specified",IFERROR(INDEX(Lookup_Tables!$B$6:$B$18,MATCH(TRIM(Raw_Data!E8),Lookup_Tables!$A$6:$A$18,0)),"Unknown - Review")) -> Vehicle Spares | F8: =IF(TRIM(Raw_Data!F8)="","",TRIM(Raw_Data!F8)) -> Truck Tyre 900x20 | G8: =IF(Raw_Data!G8="","",IF(VALUE(Raw_Data!G8)<=0,"Invalid",VALUE(Raw_Data!G8))) -> 103 | H8: =IF(Raw_Data!H8="","",IF(VALUE(Raw_Data!H8)<=0,"Invalid",VALUE(Raw_Data!H8))) -> 85 | I8: =IFERROR(VALUE(SUBSTITUTE(SUBSTITUTE(Raw_Data!I8,"₹",""),",","")),"") -> 12643 | J8: =IF(TRIM(Raw_Data!J8)="","Not Specified",PROPER(TRIM(Raw_Data!J8))) -> High | K8: =IF(TRIM(Raw_Data!K8)="","Not Specified",IFERROR(INDEX(Lookup_Tables!$E$6:$E$13,MATCH(TRIM(Raw_Data!K8),Lookup_Tables!$D$6:$D$13,0)),"Unknown - Review")) -> Delivered | L8: =IF(TRIM(Raw_Data!L8)="","",PROPER(TRIM(Raw_Data!L8))) -> Logistics Officer | M8: =IF(Raw_Data!M8="","",IF(ISNUMBER(Raw_Data!M8),Raw_Data!M8,IF(ISNUMBER(SEARCH("/",Raw_Data!M8)),IFERROR(DATE(VALUE(RIGHT(Raw_Data!M8,4)),VALUE(MID(Raw_Data!M8,4,2)),VALUE(LEFT(Raw_Data!M8,2))),"Invalid Date"),IFERROR(DATEVALUE(Raw_Data!M8),"Invalid Date")))) -> 45868 | N8: =IF(Raw_Data!N8="","",IF(ISNUMBER(Raw_Data!N8),Raw_Data!N8,IF(ISNUMBER(SEARCH("/",Raw_Data!N8)),IFERROR(DATE(VALUE(RIGHT(Raw_Data!N8,4)),VALUE(MID(Raw_Data!N8,4,2)),VALUE(LEFT(Raw_Data!N8,2))),"Invalid Date"),IFERROR(DATEVALUE(Raw_Data!N8),"Invalid Date")))) -> 45875 | O8: =IF(Raw_Data!O8="","",IF(ISNUMBER(Raw_Data!O8),Raw_Data!O8,IF(ISNUMBER(SEARCH("/",Raw_Data!O8)),IFERROR(DATE(VALUE(RIGHT(Raw_Data!O8,4)),VALUE(MID(Raw_Data!O8,4,2)),VALUE(LEFT(Raw_Data!O8,2))),"Invalid Date"),IFERROR(DATEVALUE(Raw_Data!O8),"Invalid Date")))) -> 45884 | P8: =IF(OR(TRIM(Raw_Data!P8)="",TRIM(Raw_Data!P8)="N/A",TRIM(Raw_Data!P8)="TBD",TRIM(Raw_Data!P8)="-"),"Not Assigned",PROPER(TRIM(Raw_Data!P8))) -> Sena Supply Co | Q8: =IF(OR(H8="",I8="",NOT(ISNUMBER(H8)),NOT(ISNUMBER(I8))),"",H8*I8) -> 1074655 | R8: =IF(AND(ISNUMBER(O8),ISNUMBER(N8)),O8-N8,"") -> 9 | S8: =IF(COUNTIF($A$2:A8,A8)>1,"Duplicate","Unique") -> Unique | T8: =IF(OR(G8="",K8="Not Specified",C8=""),"Yes","No") -> No | U8: =IF(OR(AND(ISNUMBER(H8),ISNUMBER(G8),H8>G8),AND(K8="Rejected",ISNUMBER(H8),H8>0)),"Yes","No") -> No | V8: =IF(AND(S8="Unique",T8="No",U8="No",G8<>"Invalid",H8<>"Invalid"),"Yes","No") -> Yes | W8: =IF(ISNUMBER(B8),TEXT(B8,"MMM-YYYY"),"")
A9: =TRIM(Raw_Data!A9) -> REQ-2025-0008 | B9: =IF(Raw_Data!B9="","",IF(ISNUMBER(Raw_Data!B9),Raw_Data!B9,IF(ISNUMBER(SEARCH("/",Raw_Data!B9)),IFERROR(DATE(VALUE(RIGHT(Raw_Data!B9,4)),VALUE(MID(Raw_Data!B9,4,2)),VALUE(LEFT(Raw_Data!B9,2))),"Invalid Date"),IFERROR(DATEVALUE(Raw_Data!B9),"Invalid Date")))) -> 45687 | C9: =IF(TRIM(Raw_Data!C9)="","",PROPER(TRIM(Raw_Data!C9))) -> Unit H - Air Defence | D9: =IF(TRIM(Raw_Data!D9)="","Not Specified",IFERROR(INDEX(Lookup_Tables!$H$6:$H$12,MATCH(TRIM(Raw_Data!D9),Lookup_Tables!$G$6:$G$12,0)),"Unknown - Review")) -> Eastern | E9: =IF(TRIM(Raw_Data!E9)="","Not Specified",IFERROR(INDEX(Lookup_Tables!$B$6:$B$18,MATCH(TRIM(Raw_Data!E9),Lookup_Tables!$A$6:$A$18,0)),"Unknown - Review")) -> Communication Equipment | F9: =IF(TRIM(Raw_Data!F9)="","",TRIM(Raw_Data!F9)) -> Signal Cable (100m) | G9: =IF(Raw_Data!G9="","",IF(VALUE(Raw_Data!G9)<=0,"Invalid",VALUE(Raw_Data!G9))) -> Invalid | H9: =IF(Raw_Data!H9="","",IF(VALUE(Raw_Data!H9)<=0,"Invalid",VALUE(Raw_Data!H9))) -> 33 | I9: =IFERROR(VALUE(SUBSTITUTE(SUBSTITUTE(Raw_Data!I9,"₹",""),",","")),"") -> 23971.01 | J9: =IF(TRIM(Raw_Data!J9)="","Not Specified",PROPER(TRIM(Raw_Data!J9))) -> High | K9: =IF(TRIM(Raw_Data!K9)="","Not Specified",IFERROR(INDEX(Lookup_Tables!$E$6:$E$13,MATCH(TRIM(Raw_Data!K9),Lookup_Tables!$D$6:$D$13,0)),"Unknown - Review")) -> Dispatched | L9: =IF(TRIM(Raw_Data!L9)="","",PROPER(TRIM(Raw_Data!L9))) -> Stores Officer | M9: =IF(Raw_Data!M9="","",IF(ISNUMBER(Raw_Data!M9),Raw_Data!M9,IF(ISNUMBER(SEARCH("/",Raw_Data!M9)),IFERROR(DATE(VALUE(RIGHT(Raw_Data!M9,4)),VALUE(MID(Raw_Data!M9,4,2)),VALUE(LEFT(Raw_Data!M9,2))),"Invalid Date"),IFERROR(DATEVALUE(Raw_Data!M9),"Invalid Date")))) -> 45688 | N9: =IF(Raw_Data!N9="","",IF(ISNUMBER(Raw_Data!N9),Raw_Data!N9,IF(ISNUMBER(SEARCH("/",Raw_Data!N9)),IFERROR(DATE(VALUE(RIGHT(Raw_Data!N9,4)),VALUE(MID(Raw_Data!N9,4,2)),VALUE(LEFT(Raw_Data!N9,2))),"Invalid Date"),IFERROR(DATEVALUE(Raw_Data!N9),"Invalid Date")))) -> 45709 | O9: =IF(Raw_Data!O9="","",IF(ISNUMBER(Raw_Data!O9),Raw_Data!O9,IF(ISNUMBER(SEARCH("/",Raw_Data!O9)),IFERROR(DATE(VALUE(RIGHT(Raw_Data!O9,4)),VALUE(MID(Raw_Data!O9,4,2)),VALUE(LEFT(Raw_Data!O9,2))),"Invalid Date"),IFERROR(DATEVALUE(Raw_Data!O9),"Invalid Date")))) | P9: =IF(OR(TRIM(Raw_Data!P9)="",TRIM(Raw_Data!P9)="N/A",TRIM(Raw_Data!P9)="TBD",TRIM(Raw_Data!P9)="-"),"Not Assigned",PROPER(TRIM(Raw_Data!P9))) -> Sena Supply Co | Q9: =IF(OR(H9="",I9="",NOT(ISNUMBER(H9)),NOT(ISNUMBER(I9))),"",H9*I9) -> 791043.33 | R9: =IF(AND(ISNUMBER(O9),ISNUMBER(N9)),O9-N9,"") | S9: =IF(COUNTIF($A$2:A9,A9)>1,"Duplicate","Unique") -> Unique | T9: =IF(OR(G9="",K9="Not Specified",C9=""),"Yes","No") -> No | U9: =IF(OR(AND(ISNUMBER(H9),ISNUMBER(G9),H9>G9),AND(K9="Rejected",ISNUMBER(H9),H9>0)),"Yes","No") -> No | V9: =IF(AND(S9="Unique",T9="No",U9="No",G9<>"Invalid",H9<>"Invalid"),"Yes","No") -> No | W9: =IF(ISNUMBER(B9),TEXT(B9,"MMM-YYYY"),"") -> Jan-2025
A10: =TRIM(Raw_Data!A10) -> REQ-2025-0009 | B10: =IF(Raw_Data!B10="","",IF(ISNUMBER(Raw_Data!B10),Raw_Data!B10,IF(ISNUMBER(SEARCH("/",Raw_Data!B10)),IFERROR(DATE(VALUE(RIGHT(Raw_Data!B10,4)),VALUE(MID(Raw_Data!B10,4,2)),VALUE(LEFT(Raw_Data!B10,2))),"Invalid Date"),IFERROR(DATEVALUE(Raw_Data!B10),"Invalid Date")))) -> 45819 | C10: =IF(TRIM(Raw_Data!C10)="","",PROPER(TRIM(Raw_Data!C10))) -> Unit C - Engineers | D10: =IF(TRIM(Raw_Data!D10)="","Not Specified",IFERROR(INDEX(Lookup_Tables!$H$6:$H$12,MATCH(TRIM(Raw_Data!D10),Lookup_Tables!$G$6:$G$12,0)),"Unknown - Review")) -> Eastern | E10: =IF(TRIM(Raw_Data!E10)="","Not Specified",IFERROR(INDEX(Lookup_Tables!$B$6:$B$18,MATCH(TRIM(Raw_Data!E10),Lookup_Tables!$A$6:$A$18,0)),"Unknown - Review")) -> Communication Equipment | F10: =IF(TRIM(Raw_Data!F10)="","",TRIM(Raw_Data!F10)) -> Antenna Unit | G10: =IF(Raw_Data!G10="","",IF(VALUE(Raw_Data!G10)<=0,"Invalid",VALUE(Raw_Data!G10))) -> 239 | H10: =IF(Raw_Data!H10="","",IF(VALUE(Raw_Data!H10)<=0,"Invalid",VALUE(Raw_Data!H10))) -> 174 | I10: =IFERROR(VALUE(SUBSTITUTE(SUBSTITUTE(Raw_Data!I10,"₹",""),",","")),"") -> 24262.9 | J10: =IF(TRIM(Raw_Data!J10)="","Not Specified",PROPER(TRIM(Raw_Data!J10))) -> High | K10: =IF(TRIM(Raw_Data!K10)="","Not Specified",IFERROR(INDEX(Lookup_Tables!$E$6:$E$13,MATCH(TRIM(Raw_Data!K10),Lookup_Tables!$D$6:$D$13,0)),"Unknown - Review")) -> Not Specified | L10: =IF(TRIM(Raw_Data!L10)="","",PROPER(TRIM(Raw_Data!L10))) -> Quartermaster | M10: =IF(Raw_Data!M10="","",IF(ISNUMBER(Raw_Data!M10),Raw_Data!M10,IF(ISNUMBER(SEARCH("/",Raw_Data!M10)),IFERROR(DATE(VALUE(RIGHT(Raw_Data!M10,4)),VALUE(MID(Raw_Data!M10,4,2)),VALUE(LEFT(Raw_Data!M10,2))),"Invalid Date"),IFERROR(DATEVALUE(Raw_Data!M10),"Invalid Date")))) -> 45828 | N10: =IF(Raw_Data!N10="","",IF(ISNUMBER(Raw_Data!N10),Raw_Data!N10,IF(ISNUMBER(SEARCH("/",Raw_Data!N10)),IFERROR(DATE(VALUE(RIGHT(Raw_Data!N10,4)),VALUE(MID(Raw_Data!N10,4,2)),VALUE(LEFT(Raw_Data!N10,2))),"Invalid Date"),IFERROR(DATEVALUE(Raw_Data!N10),"Invalid Date")))) -> 45841 | O10: =IF(Raw_Data!O10="","",IF(ISNUMBER(Raw_Data!O10),Raw_Data!O10,IF(ISNUMBER(SEARCH("/",Raw_Data!O10)),IFERROR(DATE(VALUE(RIGHT(Raw_Data!O10,4)),VALUE(MID(Raw_Data!O10,4,2)),VALUE(LEFT(Raw_Data!O10,2))),"Invalid Date"),IFERROR(DATEVALUE(Raw_Data!O10),"Invalid Date")))) -> 45840 | P10: =IF(OR(TRIM(Raw_Data!P10)="",TRIM(Raw_Data!P10)="N/A",TRIM(Raw_Data!P10)="TBD",TRIM(Raw_Data!P10)="-"),"Not Assigned",PROPER(TRIM(Raw_Data!P10))) -> Om Suppliers | Q10: =IF(OR(H10="",I10="",NOT(ISNUMBER(H10)),NOT(ISNUMBER(I10))),"",H10*I10) -> 4221744.6 | R10: =IF(AND(ISNUMBER(O10),ISNUMBER(N10)),O10-N10,"") -> -1 | S10: =IF(COUNTIF($A$2:A10,A10)>1,"Duplicate","Unique") -> Unique | T10: =IF(OR(G10="",K10="Not Specified",C10=""),"Yes","No") -> Yes | U10: =IF(OR(AND(ISNUMBER(H10),ISNUMBER(G10),H10>G10),AND(K10="Rejected",ISNUMBER(H10),H10>0)),"Yes","No") -> No | V10: =IF(AND(S10="Unique",T10="No",U10="No",G10<>"Invalid",H10<>"Invalid"),"Yes","No") -> No | W10: =IF(ISNUMBER(B10),TEXT(B10,"MMM-YYYY"),"") -> Jun-2025
A11: =TRIM(Raw_Data!A11) -> REQ-2025-0010 | B11: =IF(Raw_Data!B11="","",IF(ISNUMBER(Raw_Data!B11),Raw_Data!B11,IF(ISNUMBER(SEARCH("/",Raw_Data!B11)),IFERROR(DATE(VALUE(RIGHT(Raw_Data!B11,4)),VALUE(MID(Raw_Data!B11,4,2)),VALUE(LEFT(Raw_Data!B11,2))),"Invalid Date"),IFERROR(DATEVALUE(Raw_Data!B11),"Invalid Date")))) -> 45802 | C11: =IF(TRIM(Raw_Data!C11)="","",PROPER(TRIM(Raw_Data!C11))) -> Unit B - Artillery | D11: =IF(TRIM(Raw_Data!D11)="","Not Specified",IFERROR(INDEX(Lookup_Tables!$H$6:$H$12,MATCH(TRIM(Raw_Data!D11),Lookup_Tables!$G$6:$G$12,0)),"Unknown - Review")) -> Southern | E11: =IF(TRIM(Raw_Data!E11)="","Not Specified",IFERROR(INDEX(Lookup_Tables!$B$6:$B$18,MATCH(TRIM(Raw_Data!E11),Lookup_Tables!$A$6:$A$18,0)),"Unknown - Review")) -> Uniforms & Clothing | F11: =IF(TRIM(Raw_Data!F11)="","",TRIM(Raw_Data!F11)) -> Field Boots (Pair) | G11: =IF(Raw_Data!G11="","",IF(VALUE(Raw_Data!G11)<=0,"Invalid",VALUE(Raw_Data!G11))) -> 356 | H11: =IF(Raw_Data!H11="","",IF(VALUE(Raw_Data!H11)<=0,"Invalid",VALUE(Raw_Data!H11))) -> 301 | I11: =IFERROR(VALUE(SUBSTITUTE(SUBSTITUTE(Raw_Data!I11,"₹",""),",","")),"") -> 40754.34 | J11: =IF(TRIM(Raw_Data!J11)="","Not Specified",PROPER(TRIM(Raw_Data!J11))) -> Low | K11: =IF(TRIM(Raw_Data!K11)="","Not Specified",IFERROR(INDEX(Lookup_Tables!$E$6:$E$13,MATCH(TRIM(Raw_Data!K11),Lookup_Tables!$D$6:$D$13,0)),"Unknown - Review")) -> Dispatched | L11: =IF(TRIM(Raw_Data!L11)="","",PROPER(TRIM(Raw_Data!L11))) -> Logistics Officer | M11: =IF(Raw_Data!M11="","",IF(ISNUMBER(Raw_Data!M11),Raw_Data!M11,IF(ISNUMBER(SEARCH("/",Raw_Data!M11)),IFERROR(DATE(VALUE(RIGHT(Raw_Data!M11,4)),VALUE(MID(Raw_Data!M11,4,2)),VALUE(LEFT(Raw_Data!M11,2))),"Invalid Date"),IFERROR(DATEVALUE(Raw_Data!M11),"Invalid Date")))) | N11: =IF(Raw_Data!N11="","",IF(ISNUMBER(Raw_Data!N11),Raw_Data!N11,IF(ISNUMBER(SEARCH("/",Raw_Data!N11)),IFERROR(DATE(VALUE(RIGHT(Raw_Data!N11,4)),VALUE(MID(Raw_Data!N11,4,2)),VALUE(LEFT(Raw_Data!N11,2))),"Invalid Date"),IFERROR(DATEVALUE(Raw_Data!N11),"Invalid Date")))) -> 45810 | O11: =IF(Raw_Data!O11="","",IF(ISNUMBER(Raw_Data!O11),Raw_Data!O11,IF(ISNUMBER(SEARCH("/",Raw_Data!O11)),IFERROR(DATE(VALUE(RIGHT(Raw_Data!O11,4)),VALUE(MID(Raw_Data!O11,4,2)),VALUE(LEFT(Raw_Data!O11,2))),"Invalid Date"),IFERROR(DATEVALUE(Raw_Data!O11),"Invalid Date")))) | P11: =IF(OR(TRIM(Raw_Data!P11)="",TRIM(Raw_Data!P11)="N/A",TRIM(Raw_Data!P11)="TBD",TRIM(Raw_Data!P11)="-"),"Not Assigned",PROPER(TRIM(Raw_Data!P11))) -> Rapid Vendors Ltd | Q11: =IF(OR(H11="",I11="",NOT(ISNUMBER(H11)),NOT(ISNUMBER(I11))),"",H11*I11) -> 12267056 | R11: =IF(AND(ISNUMBER(O11),ISNUMBER(N11)),O11-N11,"") | S11: =IF(COUNTIF($A$2:A11,A11)>1,"Duplicate","Unique") -> Unique | T11: =IF(OR(G11="",K11="Not Specified",C11=""),"Yes","No") -> No | U11: =IF(OR(AND(ISNUMBER(H11),ISNUMBER(G11),H11>G11),AND(K11="Rejected",ISNUMBER(H11),H11>0)),"Yes","No") -> No | V11: =IF(AND(S11="Unique",T11="No",U11="No",G11<>"Invalid",H11<>"Invalid"),"Yes","No") -> Yes | W11: =IF(ISNUMBER(B11),TEXT(B11,"MMM-YYYY"),"") -> May-2025
A12: =TRIM(Raw_Data!A12) -> REQ-2025-0011 | B12: =IF(Raw_Data!B12="","",IF(ISNUMBER(Raw_Data!B12),Raw_Data!B12,IF(ISNUMBER(SEARCH("/",Raw_Data!B12)),IFERROR(DATE(VALUE(RIGHT(Raw_Data!B12,4)),VALUE(MID(Raw_Data!B12,4,2)),VALUE(LEFT(Raw_Data!B12,2))),"Invalid Date"),IFERROR(DATEVALUE(Raw_Data!B12),"Invalid Date")))) -> 45765 | C12: =IF(TRIM(Raw_Data!C12)="","",PROPER(TRIM(Raw_Data!C12))) -> Unit A - Infantry | D12: =IF(TRIM(Raw_Data!D12)="","Not Specified",IFERROR(INDEX(Lookup_Tables!$H$6:$H$12,MATCH(TRIM(Raw_Data!D12),Lookup_Tables!$G$6:$G$12,0)),"Unknown - Review")) -> Northern | E12: =IF(TRIM(Raw_Data!E12)="","Not Specified",IFERROR(INDEX(Lookup_Tables!$B$6:$B$18,MATCH(TRIM(Raw_Data!E12),Lookup_Tables!$A$6:$A$18,0)),"Unknown - Review")) -> Rations | F12: =IF(TRIM(Raw_Data!F12)="","",TRIM(Raw_Data!F12)) -> Rice (50kg bag) | G12: =IF(Raw_Data!G12="","",IF(VALUE(Raw_Data!G12)<=0,"Invalid",VALUE(Raw_Data!G12))) -> 404 | H12: =IF(Raw_Data!H12="","",IF(VALUE(Raw_Data!H12)<=0,"Invalid",VALUE(Raw_Data!H12))) -> 400 | I12: =IFERROR(VALUE(SUBSTITUTE(SUBSTITUTE(Raw_Data!I12,"₹",""),",","")),"") -> 33764.07 | J12: =IF(TRIM(Raw_Data!J12)="","Not Specified",PROPER(TRIM(Raw_Data!J12))) -> High | K12: =IF(TRIM(Raw_Data!K12)="","Not Specified",IFERROR(INDEX(Lookup_Tables!$E$6:$E$13,MATCH(TRIM(Raw_Data!K12),Lookup_Tables!$D$6:$D$13,0)),"Unknown - Review")) -> Delivered | L12: =IF(TRIM(Raw_Data!L12)="","",PROPER(TRIM(Raw_Data!L12))) -> Stores Officer | M12: =IF(Raw_Data!M12="","",IF(ISNUMBER(Raw_Data!M12),Raw_Data!M12,IF(ISNUMBER(SEARCH("/",Raw_Data!M12)),IFERROR(DATE(VALUE(RIGHT(Raw_Data!M12,4)),VALUE(MID(Raw_Data!M12,4,2)),VALUE(LEFT(Raw_Data!M12,2))),"Invalid Date"),IFERROR(DATEVALUE(Raw_Data!M12),"Invalid Date")))) -> 45769 | N12: =IF(Raw_Data!N12="","",IF(ISNUMBER(Raw_Data!N12),Raw_Data!N12,IF(ISNUMBER(SEARCH("/",Raw_Data!N12)),IFERROR(DATE(VALUE(RIGHT(Raw_Data!N12,4)),VALUE(MID(Raw_Data!N12,4,2)),VALUE(LEFT(Raw_Data!N12,2))),"Invalid Date"),IFERROR(DATEVALUE(Raw_Data!N12),"Invalid Date")))) -> 45779 | O12: =IF(Raw_Data!O12="","",IF(ISNUMBER(Raw_Data!O12),Raw_Data!O12,IF(ISNUMBER(SEARCH("/",Raw_Data!O12)),IFERROR(DATE(VALUE(RIGHT(Raw_Data!O12,4)),VALUE(MID(Raw_Data!O12,4,2)),VALUE(LEFT(Raw_Data!O12,2))),"Invalid Date"),IFERROR(DATEVALUE(Raw_Data!O12),"Invalid Date")))) -> 45799 | P12: =IF(OR(TRIM(Raw_Data!P12)="",TRIM(Raw_Data!P12)="N/A",TRIM(Raw_Data!P12)="TBD",TRIM(Raw_Data!P12)="-"),"Not Assigned",PROPER(TRIM(Raw_Data!P12))) -> National Defence Stores | Q12: =IF(OR(H12="",I12="",NOT(ISNUMBER(H12)),NOT(ISNUMBER(I12))),"",H12*I12) -> 13505628 | R12: =IF(AND(ISNUMBER(O12),ISNUMBER(N12)),O12-N12,"") -> 20 | S12: =IF(COUNTIF($A$2:A12,A12)>1,"Duplicate","Unique") -> Unique | T12: =IF(OR(G12="",K12="Not Specified",C12=""),"Yes","No") -> No | U12: =IF(OR(AND(ISNUMBER(H12),ISNUMBER(G12),H12>G12),AND(K12="Rejected",ISNUMBER(H12),H12>0)),"Yes","No") -> No | V12: =IF(AND(S12="Unique",T12="No",U12="No",G12<>"Invalid",H12<>"Invalid"),"Yes","No") -> Yes | W12: =IF(ISNUMBER(B12),TEXT(B12,"MMM-YYYY"),"") -> Apr-2025
A13: =TRIM(Raw_Data!A13) -> REQ-2025-0012 | B13: =IF(Raw_Data!B13="","",IF(ISNUMBER(Raw_Data!B13),Raw_Data!B13,IF(ISNUMBER(SEARCH("/",Raw_Data!B13)),IFERROR(DATE(VALUE(RIGHT(Raw_Data!B13,4)),VALUE(MID(Raw_Data!B13,4,2)),VALUE(LEFT(Raw_Data!B13,2))),"Invalid Date"),IFERROR(DATEVALUE(Raw_Data!B13),"Invalid Date")))) -> 45826 | C13: =IF(TRIM(Raw_Data!C13)="","",PROPER(TRIM(Raw_Data!C13))) -> Unit D - Signals | D13: =IF(TRIM(Raw_Data!D13)="","Not Specified",IFERROR(INDEX(Lookup_Tables!$H$6:$H$12,MATCH(TRIM(Raw_Data!D13),Lookup_Tables!$G$6:$G$12,0)),"Unknown - Review")) -> Western | E13: =IF(TRIM(Raw_Data!E13)="","Not Specified",IFERROR(INDEX(Lookup_Tables!$B$6:$B$18,MATCH(TRIM(Raw_Data!E13),Lookup_Tables!$A$6:$A$18,0)),"Unknown - Review")) -> Medical Supplies | F13: =IF(TRIM(Raw_Data!F13)="","",TRIM(Raw_Data!F13)) -> Antiseptic Solution (5L) | G13: =IF(Raw_Data!G13="","",IF(VALUE(Raw_Data!G13)<=0,"Invalid",VALUE(Raw_Data!G13))) -> 184 | H13: =IF(Raw_Data!H13="","",IF(VALUE(Raw_Data!H13)<=0,"Invalid",VALUE(Raw_Data!H13))) -> 182 | I13: =IFERROR(VALUE(SUBSTITUTE(SUBSTITUTE(Raw_Data!I13,"₹",""),",","")),"") -> 24199 | J13: =IF(TRIM(Raw_Data!J13)="","Not Specified",PROPER(TRIM(Raw_Data!J13))) -> High | K13: =IF(TRIM(Raw_Data!K13)="","Not Specified",IFERROR(INDEX(Lookup_Tables!$E$6:$E$13,MATCH(TRIM(Raw_Data!K13),Lookup_Tables!$D$6:$D$13,0)),"Unknown - Review")) -> Approved | L13: =IF(TRIM(Raw_Data!L13)="","",PROPER(TRIM(Raw_Data!L13))) -> Stores Officer | M13: =IF(Raw_Data!M13="","",IF(ISNUMBER(Raw_Data!M13),Raw_Data!M13,IF(ISNUMBER(SEARCH("/",Raw_Data!M13)),IFERROR(DATE(VALUE(RIGHT(Raw_Data!M13,4)),VALUE(MID(Raw_Data!M13,4,2)),VALUE(LEFT(Raw_Data!M13,2))),"Invalid Date"),IFERROR(DATEVALUE(Raw_Data!M13),"Invalid Date")))) | N13: =IF(Raw_Data!N13="","",IF(ISNUMBER(Raw_Data!N13),Raw_Data!N13,IF(ISNUMBER(SEARCH("/",Raw_Data!N13)),IFERROR(DATE(VALUE(RIGHT(Raw_Data!N13,4)),VALUE(MID(Raw_Data!N13,4,2)),VALUE(LEFT(Raw_Data!N13,2))),"Invalid Date"),IFERROR(DATEVALUE(Raw_Data!N13),"Invalid Date")))) -> 45835 | O13: =IF(Raw_Data!O13="","",IF(ISNUMBER(Raw_Data!O13),Raw_Data!O13,IF(ISNUMBER(SEARCH("/",Raw_Data!O13)),IFERROR(DATE(VALUE(RIGHT(Raw_Data!O13,4)),VALUE(MID(Raw_Data!O13,4,2)),VALUE(LEFT(Raw_Data!O13,2))),"Invalid Date"),IFERROR(DATEVALUE(Raw_Data!O13),"Invalid Date")))) | P13: =IF(OR(TRIM(Raw_Data!P13)="",TRIM(Raw_Data!P13)="N/A",TRIM(Raw_Data!P13)="TBD",TRIM(Raw_Data!P13)="-"),"Not Assigned",PROPER(TRIM(Raw_Data!P13))) -> Shakti Traders | Q13: =IF(OR(H13="",I13="",NOT(ISNUMBER(H13)),NOT(ISNUMBER(I13))),"",H13*I13) -> 4404218 | R13: =IF(AND(ISNUMBER(O13),ISNUMBER(N13)),O13-N13,"") | S13: =IF(COUNTIF($A$2:A13,A13)>1,"Duplicate","Unique") -> Unique | T13: =IF(OR(G13="",K13="Not Specified",C13=""),"Yes","No") -> No | U13: =IF(OR(AND(ISNUMBER(H13),ISNUMBER(G13),H13>G13),AND(K13="Rejected",ISNUMBER(H13),H13>0)),"Yes","No") -> No | V13: =IF(AND(S13="Unique",T13="No",U13="No",G13<>"Invalid",H13<>"Invalid"),"Yes","No") -> Yes | W13: =IF(ISNUMBER(B13),TEXT(B13,"MMM-YYYY"),"") -> Jun-2025
... A301: =TRIM(Raw_Data!A301) -> REQ-2025-0117 | B301: =IF(Raw_Data!B301="","",IF(ISNUMBER(Raw_Data!B301),Raw_Data!B301,IF(ISNUMBER(SEARCH("/",Raw_Data!B301)),IFERROR(DATE(VALUE(RIGHT(Raw_Data!B301,4)),VALUE(MID(Raw_Data!B301,4,2)),VALUE(LEFT(Raw_Data!B301,2))),"Invalid Date"),IFERROR(DATEVALUE(Raw_Data!B301),"Invalid Date")))) -> 45861 | C301: =IF(TRIM(Raw_Data!C301)="","",PROPER(TRIM(Raw_Data!C301))) -> Unit G - Transport Corps | D301: =IF(TRIM(Raw_Data!D301)="","Not Specified",IFERROR(INDEX(Lookup_Tables!$H$6:$H$12,MATCH(TRIM(Raw_Data!D301),Lookup_Tables!$G$6:$G$12,0)),"Unknown - Review")) -> Southern | E301: =IF(TRIM(Raw_Data!E301)="","Not Specified",IFERROR(INDEX(Lookup_Tables!$B$6:$B$18,MATCH(TRIM(Raw_Data!E301),Lookup_Tables!$A$6:$A$18,0)),"Unknown - Review")) -> Medical Supplies | F301: =IF(TRIM(Raw_Data!F301)="","",TRIM(Raw_Data!F301)) -> Bandage Roll (Pack) | G301: =IF(Raw_Data!G301="","",IF(VALUE(Raw_Data!G301)<=0,"Invalid",VALUE(Raw_Data!G301))) -> 417 | H301: =IF(Raw_Data!H301="","",IF(VALUE(Raw_Data!H301)<=0,"Invalid",VALUE(Raw_Data!H301))) -> 379 | I301: =IFERROR(VALUE(SUBSTITUTE(SUBSTITUTE(Raw_Data!I301,"₹",""),",","")),"") -> 33717 | J301: =IF(TRIM(Raw_Data!J301)="","Not Specified",PROPER(TRIM(Raw_Data!J301))) -> Low | K301: =IF(TRIM(Raw_Data!K301)="","Not Specified",IFERROR(INDEX(Lookup_Tables!$E$6:$E$13,MATCH(TRIM(Raw_Data!K301),Lookup_Tables!$D$6:$D$13,0)),"Unknown - Review")) -> Delivered | L301: =IF(TRIM(Raw_Data!L301)="","",PROPER(TRIM(Raw_Data!L301))) -> Unit Commander | M301: =IF(Raw_Data!M301="","",IF(ISNUMBER(Raw_Data!M301),Raw_Data!M301,IF(ISNUMBER(SEARCH("/",Raw_Data!M301)),IFERROR(DATE(VALUE(RIGHT(Raw_Data!M301,4)),VALUE(MID(Raw_Data!M301,4,2)),VALUE(LEFT(Raw_Data!M301,2))),"Invalid Date"),IFERROR(DATEVALUE(Raw_Data!M301),"Invalid Date")))) -> 45866 | N301: =IF(Raw_Data!N301="","",IF(ISNUMBER(Raw_Data!N301),Raw_Data!N301,IF(ISNUMBER(SEARCH("/",Raw_Data!N301)),IFERROR(DATE(VALUE(RIGHT(Raw_Data!N301,4)),VALUE(MID(Raw_Data!N301,4,2)),VALUE(LEFT(Raw_Data!N301,2))),"Invalid Date"),IFERROR(DATEVALUE(Raw_Data!N301),"Invalid Date")))) | O301: =IF(Raw_Data!O301="","",IF(ISNUMBER(Raw_Data!O301),Raw_Data!O301,IF(ISNUMBER(SEARCH("/",Raw_Data!O301)),IFERROR(DATE(VALUE(RIGHT(Raw_Data!O301,4)),VALUE(MID(Raw_Data!O301,4,2)),VALUE(LEFT(Raw_Data!O301,2))),"Invalid Date"),IFERROR(DATEVALUE(Raw_Data!O301),"Invalid Date")))) -> 45905 | P301: =IF(OR(TRIM(Raw_Data!P301)="",TRIM(Raw_Data!P301)="N/A",TRIM(Raw_Data!P301)="TBD",TRIM(Raw_Data!P301)="-"),"Not Assigned",PROPER(TRIM(Raw_Data!P301))) -> Om Suppliers | Q301: =IF(OR(H301="",I301="",NOT(ISNUMBER(H301)),NOT(ISNUMBER(I301))),"",H301*I301) -> 12778743 | R301: =IF(AND(ISNUMBER(O301),ISNUMBER(N301)),O301-N301,"") | S301: =IF(COUNTIF($A$2:A301,A301)>1,"Duplicate","Unique") -> Duplicate | T301: =IF(OR(G301="",K301="Not Specified",C301=""),"Yes","No") -> No | U301: =IF(OR(AND(ISNUMBER(H301),ISNUMBER(G301),H301>G301),AND(K301="Rejected",ISNUMBER(H301),H301>0)),"Yes","No") -> No | V301: =IF(AND(S301="Unique",T301="No",U301="No",G301<>"Invalid",H301<>"Invalid"),"Yes","No") -> No | W301: =IF(ISNUMBER(B301),TEXT(B301,"MMM-YYYY"),"") -> Jul-2025

Sheet Data_Cleaning_Log
B2: Data Cleaning Log
B3: Every count below is a live formula against Cleaned_Data — it updates automatically if Raw_Data changes.
B5: # | C5: Issue Found in Raw Data | D5: Technique / Formula Used | E5: Example | F5: Rows Affected
B6: 1 | C6: Inconsistent case / stray whitespace in text fields (Unit, Region, Category, Status, Priority, Vendor) | D6: TRIM() + PROPER() to standardize casing and collapse extra spaces | E6: "unit b - artillery" / " Unit G " -> "Unit B - Artillery" | F6: =SUMPRODUCT(--(EXACT(TRIM(Raw_Data!C2:C301),Raw_Data!C2:C301)=FALSE())) -> 55
B7: 2 | C7: Genuine misspellings in Category / Status / Region (not just case) | D7: INDEX/MATCH against a Messy-to-Canonical lookup table on Lookup_Tables | E7: "Raitons" -> "Rations", "Pendng" -> "Pending", "Nothern" -> "Northern" | F7: =COUNTIF(Cleaned_Data!E2:E301,"Unknown - Review")+COUNTIF(Cleaned_Data!K2:K301,"Unknown - Review")+COUNTIF(Cleaned_Data!D2:D301,"Unknown - Review") -> 0
B8: 3 | C8: Dates stored as 3 different shapes: true dates, DD/MM/YYYY text, DD-Mon-YYYY text | D8: ISNUMBER() branch for true dates; fixed-width DATE(RIGHT/MID/LEFT) for slash dates (DATEVALUE alone mis-reads DD/MM as MM/DD under a US locale); DATEVALUE for named-month text | E8: "25/04/2025" -> 25-Apr-2025 (not misread as month 25) | F8: =COUNTIF(Cleaned_Data!B2:B301,"Invalid Date") -> 0
B9: 4 | C9: Cost stored as text with currency symbol and thousand separators | D9: SUBSTITUTE() to strip "₹" and "," then VALUE() to convert to a real number, wrapped in IFERROR | E9: "₹27,891" -> 27891 | F9: =SUMPRODUCT(--(ISNUMBER(Cleaned_Data!I2:I301))) -> 273
B10: 5 | C10: Missing values in required fields (Quantity, Status, Unit) | D10: Blank checks roll up into a Missing_Critical_Data flag column | E10: Blank Status -> flagged "Not Specified", row excluded from analysis | F10: =COUNTIF(Cleaned_Data!T2:T301,"Yes") -> 18
B11: 6 | C11: Invalid quantities: zero, negative, or text entry errors | D11: VALUE() parse wrapped with a <=0 check, flags the cell "Invalid" | E11: -307 or 0 units requested -> flagged "Invalid" | F11: =COUNTIF(Cleaned_Data!G2:G301,"Invalid")+COUNTIF(Cleaned_Data!H2:H301,"Invalid") -> 18
B12: 7 | C12: Logic errors: Quantity Approved > Quantity Requested, or a Rejected requisition with an approved quantity | D12: Cross-field AND/OR comparison into a Logic_Error_Flag column | E12: Requested 100, Approved 140 -> flagged | F12: =COUNTIF(Cleaned_Data!U2:U301,"Yes") -> 12
B13: 8 | C13: Duplicate requisitions (same Req_ID submitted more than once) | D13: Running COUNTIF($A$2:A_row, A_row) — first occurrence kept, later ones flagged | E13: REQ-2025-0032 appears twice -> 2nd occurrence flagged "Duplicate" | F13: =COUNTIF(Cleaned_Data!S2:S301,"Duplicate") -> 15
B14: 9 | C14: Vendor field placeholders instead of true blanks | D14: IF/OR() maps "N/A", "TBD", "-", and blank all to one consistent "Not Assigned" label | E14: "TBD" / "-" / "" -> "Not Assigned" | F14: =COUNTIF(Cleaned_Data!P2:P301,"Not Assigned") -> 46
B16: Overall Data Quality
B17: Total rows in Raw_Data: | C17: =COUNTA(Cleaned_Data!A2:A301) -> 300
B18: Rows passing all checks (Include_In_Analysis = Yes): | C18: =COUNTIF(Cleaned_Data!V2:V301,"Yes") -> 238
B19: Data quality rate: | C19: =C18/C17 -> 0.79333333

Sheet New_Entry_Form
B2: New Requisition Entry Form
B3: Add new requisitions here. Dropdowns and range checks below prevent the same data-quality issues found in Raw_Data from entering the system going forward.
B5: Req_ID | C5: Request_Date | D5: Unit | E5: Region | F5: Item_Category | G5: Item_Name | H5: Quantity_Requested | I5: Priority | J5: Status | K5: Requested_By_Role | L5: Vendor | M5: Unit_Cost_INR
B6: REQ-2026-0001 | C6: 46037 | D6: Unit A - Infantry | E6: Northern | F6: Rations | G6: Dry Ration Pack | H6: 120 | I6: High | J6: Pending | K6: Quartermaster | L6: Bharat Logistics Pvt Ltd | M6: 850 | N6: <- example row, showing expected format (edit or delete)
B33: Validation rules applied:
B34: • Request_Date: must be a valid date on/after 01/01/2020
B35: • Unit / Region / Item_Category / Priority / Status / Requested_By_Role: dropdown list, no free text allowed
B36: • Quantity_Requested: whole number, must be greater than 0
B37: • Unit_Cost_INR: decimal number, must be greater than 0, no currency symbol

Sheet Pivot_Unit_Status
B2: Requisitions by Unit & Status
B3: Count of requisitions. Only rows where Cleaned_Data!Include_In_Analysis = "Yes" are counted.
B5: Unit | C5: Pending | D5: Approved | E5: Rejected | F5: Dispatched | G5: Delivered | H5: Total Requisitions | I5: Total Cost (INR)
